Workbook

Sheet Dashboard
A1: FLOW METRICS + BURNDOWN DASHBOARD
A2: SaaS Offshore JP | 3 Dev · 2 QA · 1 PM | Sprint 1W | Capacity 70-75% | TAT CA CONG THUC TU DONG
A3: Moi so lieu tren Dashboard nay deu la CONG THUC doc tu cac sheet khac — KHONG CAN NHAP TAY. Tuong thich Google Sheets.
A5: KEY PERFORMANCE INDICATORS — Tu dong tu Item Log + Weekly Data
A6: TONG ITEMS | D6: ITEMS DONE | G6: WIP HIEN TAI | J6: AVG THROUGHPUT | M6: CYCLE TIME P85 | P6: LITTLE'S LAW
A7: 48 | D7: ='Item Log'!F55 -> 36 | G7: ='Item Log'!F56+'Item Log'!F57+'Item Log'!F58 -> 12 | J7: =IFERROR(AVERAGE('Weekly Data'!F5:F14),"") -> 5.7 | M7: =IFERROR(PERCENTILE('Item Log'!S4:S51,0.85),"") -> 10.75 | P7: =IFERROR(('Item Log'!F56+'Item Log'!F57+'Item Log'!F58)/AVERAGE('Weekly Data'!F5:F14),"") -> 2.1052632
A8: items du an | D8: items hoan thanh | G8: items dang xu ly | J8: items / tuan | M8: ngay (calendar) | P8: ngay (WIP / Throughput)
A9: ="Done: "&'Item Log'!F55&" | Con: "&(48-'Item Log'!F55) -> Done: 36 | Con: 12 | D9: =TEXT('Item Log'!F67,"0.0%")&" completion" -> 75.0% completion | G9: ="Dev: "&'Item Log'!F56&" | QA: "&'Item Log'!F57&" | Final: "&'Item Log'!F58 -> Dev: 3 | QA: 8 | Final: 1 | J9: ="Min: "&MIN('Weekly Data'!F5:F14)&" | Max: "&MAX('Weekly Data'!F5:F14) -> Min: 3 | Max: 8 | M9: ="P50: "&ROUND(MEDIAN('Item Log'!S4:S51),0)&"d | Avg: "&ROUND(AVERAGEIF('Item Log'!S4:S51,">0"),1)&"d" -> P50: 9d | Avg: 8.8d | P9: CT du doan tu Dinh luat Little
A11: TIEN DO DU AN | G11: CAPACITY & GIO | M11: BURNDOWN STATUS
A12: Chi So | B12: Gia Tri (Cong Thuc) | G12: Metric | H12: Value | M12: Metric | N12: Value
A13: Tong Items | D13: =48 -> 48 | G13: Gross Hours/Tuan (3 Dev) | J13: =3*8*5 -> 120 | M13: Tuan Hien Tai | P13: =COUNTA('Weekly Data'!A5:A14) -> 10
A14: Items Done | D14: ='Item Log'!F55 -> 36 | G14: Target 72.5% | J14: =ROUND(3*8*5*0.725,0) -> 87 | M14: Items Con Lai (Actual) | P14: =48-'Item Log'!F55 -> 12
A15: Items Con Lai | D15: =48-'Item Log'!F55 -> 12 | G15: Overhead 27.5% | J15: =ROUND(3*8*5*0.275,0) -> 33 | M15: Best Case (Ideal) | P15: =MAX(0,48-48/10*COUNTA('Weekly Data'!A5:A14)) -> 0
A16: % Done (Items) | D16: ='Item Log'!F67 -> 0.75 | G16: Tong Gio Estimate | J16: ='Item Log'!F64 -> 888 | M16: Worst Case (Buffer) | P16: =MAX(0,48-48*POWER(COUNTA('Weekly Data'!A5:A14)/(10*1.2),1.3)) -> 10.129101
A17: % Done (Gio) | D17: ='Item Log'!F68 -> 0.71171171 | G17: Gio Done | J17: ='Item Log'!F65 -> 632 | M17: Actual vs Best | P17: =(48-'Item Log'!F55)-MAX(0,48-48/10*COUNTA('Weekly Data'!A5:A14)) -> 12
A18: Tuan Hien Tai | D18: =COUNTA('Weekly Data'!A5:A14) -> 10 | G18: Gio Con Lai | J18: ='Item Log'!F66 -> 256 | M18: Actual vs Worst | P18: =(48-'Item Log'!F55)-MAX(0,48-48*POWER(COUNTA('Weekly Data'!A5:A14)/(10*1.2),1.3)) -> 1.8708992
A19: Items Done Ly Tuong | D19: =ROUND(48/(10)*COUNTA('Weekly Data'!A5:A14),0) -> 48 | G19: Avg Gio / Item (Done) | J19: =IFERROR('Item Log'!F65/'Item Log'!F55,"") -> 17.555556 | M19: Burndown Zone | P19: =IF((48-'Item Log'!F55)<=MAX(0,48-48/10*COUNTA('Weekly Data'!A5:A14)),"NHANH",IF((48-'Item Log'!F55)<=MAX(0,48-48*POWER(COUNTA('Weekly Data'!A5:A14)/(10*1.2),1.3)),"OK","CHAM")) -> CHAM
A20: Delta vs Ly Tuong | D20: ='Item Log'!F55-ROUND(48/10*COUNTA('Weekly Data'!A5:A14),0) -> -12 | G20: Tuan Con Lai (by Gio) | J20: =IFERROR('Item Log'!F66/(3*8*5*0.725),"") -> 2.9425287 | M20: Forecast 85% (tuan) | P20: ='Monte Carlo'!B14 -> -3
A22: WIP THEO TUNG BUOC — DEV + QA + FINAL (Cong thuc tu Item Log) | J22: THROUGHPUT & CYCLE TIME THEO TUAN (Cong thuc tu Weekly Data)
A23: Buoc | B23: Phase | C23: WIP Hien Tai | D23: Limit | E23: Delta | F23: Status | G23: Reviewer | J23: Tuan | K23: Items Done | L23: Gio Done | M23: Tich Luy | N23: Best | O23: Actual | P23: Worst | Q23: Status | R23: CT Avg
A24: Detail Design | B24: Dev | C24: =COUNTIF('Item Log'!U4:U51,A24) -> 0 | D24: -- | E24: -- | F24: -- | J24: ='Weekly Data'!A5 -> W01 | K24: ='Weekly Data'!F5 -> 6 | L24: ='Weekly Data'!G5 -> 108 | M24: ='Weekly Data'!H5 -> 7 | N24: ='Weekly Data'!K5 -> 43.2 | O24: ='Weekly Data'!J5 -> 41 | P24: ='Weekly Data'!L5 -> 46.101959 | Q24: ='Weekly Data'!R5 -> Nhanh | R24: =IFERROR('Weekly Data'!M5,"") -> 6
A25: Review Design | B25: Dev | C25: =COUNTIF('Item Log'!U4:U51,A25) -> 0 | D25: 2 | E25: =IF(D25="--","",C25-D25) -> -2 | F25: =IF(D25="--","",IF(C25>D25,"VUOT",IF(C25=D25,"SAT","OK"))) -> OK | G25: Cross-review: Dev khac | J25: ='Weekly Data'!A6 -> W02 | K25: ='Weekly Data'!F6 -> 7 | L25: ='Weekly Data'!G6 -> 98 | M25: ='Weekly Data'!H6 -> 14 | N25: ='Weekly Data'!K6 -> 38.4 | O25: ='Weekly Data'!J6 -> 34 | P25: ='Weekly Data'!L6 -> 43.326475 | Q25: ='Weekly Data'!R6 -> Nhanh | R25: =IFERROR('Weekly Data'!M6,"") -> 6.5
A26: Coding | B26: Dev | C26: =COUNTIF('Item Log'!U4:U51,A26) -> 0 | D26: 3 | E26: =IF(D26="--","",C26-D26) -> -3 | F26: =IF(D26="--","",IF(C26>D26,"VUOT",IF(C26=D26,"SAT","OK"))) -> OK | G26: 1 Dev = 1 item | J26: ='Weekly Data'!A7 -> W03 | K26: ='Weekly Data'!F7 -> 7 | L26: ='Weekly Data'!G7 -> 119 | M26: ='Weekly Data'!H7 -> 21 | N26: ='Weekly Data'!K7 -> 33.6 | O26: ='Weekly Data'!J7 -> 27 | P26: ='Weekly Data'!L7 -> 40.082953 | Q26: ='Weekly Data'!R7 -> Nhanh | R26: =IFERROR('Weekly Data'!M7,"") -> 6.6666667
A27: Review Code | B27: Dev | C27: =COUNTIF('Item Log'!U4:U51,A27) -> 1 | D27: 2 | E27: =IF(D27="--","",C27-D27) -> -1 | F27: =IF(D27="--","",IF(C27>D27,"VUOT",IF(C27=D27,"SAT","OK"))) -> OK | G27: Cross-review: Dev khac | J27: ='Weekly Data'!A8 -> W04 | K27: ='Weekly Data'!F8 -> 3 | L27: ='Weekly Data'!G8 -> 51 | M27: ='Weekly Data'!H8 -> 24 | N27: ='Weekly Data'!K8 -> 28.8 | O27: ='Weekly Data'!J8 -> 24 | P27: ='Weekly Data'!L8 -> 36.492431 | Q27: ='Weekly Data'!R8 -> Nhanh | R27: =IFERROR('Weekly Data'!M8,"") -> 5.75
A28: Whitebox | B28: Dev | C28: =COUNTIF('Item Log'!U4:U51,A28) -> 2 | D28: 2 | E28: =IF(D28="--","",C28-D28) -> 0 | F28: =IF(D28="--","",IF(C28>D28,"VUOT",IF(C28=D28,"SAT","OK"))) -> OK | G28: Unit test boi Dev | J28: ='Weekly Data'!A9 -> W05 | K28: ='Weekly Data'!F9 -> 4 | L28: ='Weekly Data'!G9 -> 68 | M28: ='Weekly Data'!H9 -> 28 | N28: ='Weekly Data'!K9 -> 24 | O28: ='Weekly Data'!J9 -> 20 | P28: ='Weekly Data'!L9 -> 32.619636 | Q28: ='Weekly Data'!R9 -> Nhanh | R28: =IFERROR('Weekly Data'!M9,"") -> 5.25
A29: Test Viewpoint | B29: QA | C29: =COUNTIF('Item Log'!U4:U51,A29) -> 0 | D29: -- | E29: -- | F29: -- | J29: ='Weekly Data'!A10 -> W06 | K29: ='Weekly Data'!F10 -> 8 | L29: ='Weekly Data'!G10 -> 152 | M29: ='Weekly Data'!H10 -> 36 | N29: ='Weekly Data'!K10 -> 19.2 | O29: ='Weekly Data'!J10 -> 12 | P29: ='Weekly Data'!L10 -> 28.505942 | Q29: ='Weekly Data'!R10 -> Nhanh | R29: =IFERROR('Weekly Data'!M10,"") -> 5.5
A30: Test Cases | B30: QA | C30: =COUNTIF('Item Log'!U4:U51,A30) -> 6 | D30: 3 | E30: =IF(D30="--","",C30-D30) -> 3 | F30: =IF(D30="--","",IF(C30>D30,"VUOT",IF(C30=D30,"SAT","OK"))) -> OK | J30: ='Weekly Data'!A11 -> W07 | K30: ='Weekly Data'!F11 -> 8 | L30: ='Weekly Data'!G11 -> 96 | M30: ='Weekly Data'!H11 -> 44 | N30: ='Weekly Data'!K11 -> 14.4 | O30: ='Weekly Data'!J11 -> 4 | P30: ='Weekly Data'!L11 -> 24.180476 | Q30: ='Weekly Data'!R11 -> Nhanh | R30: =IFERROR('Weekly Data'!M11,"") -> 5.75
A31: Review TC | B31: QA | C31: =COUNTIF('Item Log'!U4:U51,A31) -> 0 | D31: 2 | E31: =IF(D31="--","",C31-D31) -> -2 | F31: =IF(D31="--","",IF(C31>D31,"VUOT",IF(C31=D31,"SAT","OK"))) -> OK | G31: Cross-review: QA khac | J31: ='Weekly Data'!A12 -> W08 | K31: ='Weekly Data'!F12 -> 7 | L31: ='Weekly Data'!G12 -> 84 | M31: ='Weekly Data'!H12 -> 51 | N31: ='Weekly Data'!K12 -> 9.6 | O31: ='Weekly Data'!J12 -> -3 | P31: ='Weekly Data'!L12 -> 19.66504 | Q31: ='Weekly Data'!R12 -> Nhanh | R31: =IFERROR('Weekly Data'!M12,"") -> 6.75
A32: Test Execute | B32: QA | C32: =COUNTIF('Item Log'!U4:U51,A32) -> 2 | D32: 3 | E32: =IF(D32="--","",C32-D32) -> -1 | F32: =IF(D32="--","",IF(C32>D32,"VUOT",IF(C32=D32,"SAT","OK"))) -> OK | J32: ='Weekly Data'!A13 -> W09 | K32: ='Weekly Data'!F13 -> 4 | L32: ='Weekly Data'!G13 -> 80 | M32: ='Weekly Data'!H13 -> 55 | N32: ='Weekly Data'!K13 -> 4.8 | O32: ='Weekly Data'!J13 -> -7 | P32: ='Weekly Data'!L13 -> 14.976669 | Q32: ='Weekly Data'!R13 -> Nhanh | R32: =IFERROR('Weekly Data'!M13,"") -> 6.75
A33: Acceptance Test | B33: Final | C33: =COUNTIF('Item Log'!U4:U51,A33) -> 0 | D33: 2 | E33: =IF(D33="--","",C33-D33) -> -2 | F33: =IF(D33="--","",IF(C33>D33,"VUOT",IF(C33=D33,"SAT","OK"))) -> OK | G33: Senior/Leader/PM | J33: ='Weekly Data'!A14 -> W10 | K33: ='Weekly Data'!F14 -> 3 | L33: ='Weekly Data'!G14 -> 57 | M33: ='Weekly Data'!H14 -> 58 | N33: ='Weekly Data'!K14 -> 0 | O33: ='Weekly Data'!J14 -> -10 | P33: ='Weekly Data'!L14 -> 10.129101 | Q33: ='Weekly Data'!R14 -> Nhanh | R33: =IFERROR('Weekly Data'!M14,"") -> 5.5
A34: TONG WIP ACTIVE | C34: =SUM(C24:C33) -> 11 | D34: 9 | E34: =C34-9 -> 2 | F34: =IF(C34>9,"VUOT LIMIT!",IF(C34>=7,"GAN LIMIT","OK")) -> VUOT LIMIT! | G34: Stop nhan moi neu vuot 9
A35: WIP Dev | C35: =SUM(C24:C28) -> 3
A36: WIP QA | C36: =SUM(C29:C32) -> 8
A37: WIP Final | C37: =SUM(C33:C33) -> 0
A39: REVIEW BOTTLENECK — 3 Khau Review (Cong thuc tu Item Log) | J39: MONTE CARLO FORECAST & LITTLE'S LAW (Tu cac sheet)
A40: Khau Review | B40: WIP | C40: Limit | D40: Status | E40: Avg Review Time | F40: Reviews > 2d | J40: Metric | K40: Value | M40: Don Vi | O40: Ghi Chu
A41: Review Design | B41: =COUNTIF('Item Log'!U4:U51,A41) -> 0 | C41: 2 | D41: =IF(B41>C41,"VUOT — BOTTLENECK!","OK") -> OK | E41: =IFERROR('Review Tracker'!D62,"") -> Dev_A | F41: =IFERROR('Review Tracker'!D64,"") -> Dev_A | J41: Items Con Lai | L41: ='Monte Carlo'!D4 -> -10 | N41: items | P41: Tu Monte Carlo
A42: Review Code | B42: =COUNTIF('Item Log'!U4:U51,A42) -> 1 | C42: 2 | D42: =IF(B42>C42,"VUOT — BOTTLENECK!","OK") -> OK | E42: =IFERROR('Review Tracker'!D63,"") -> Dev_B | F42: =IFERROR('Review Tracker'!D64,"") -> Dev_A | J42: Avg Throughput | L42: ='Monte Carlo'!D5 -> 5.7 | N42: items/w | P42: Lich su
A43: Review TC | B43: =COUNTIF('Item Log'!U4:U51,A43) -> 0 | C43: 2 | D43: =IF(B43>C43,"VUOT — BOTTLENECK!","OK") -> OK | E43: =IFERROR('Review Tracker'!D64,"") -> Dev_A | F43: =IFERROR('Review Tracker'!D64,"") -> Dev_A | J43: Forecast 50% | L43: ='Monte Carlo'!B12 -> -2 | N43: tuan | P43: Xac suat 50:50
J44: Forecast 70% | L44: ='Monte Carlo'!B13 -> -2 | N44: tuan | P44: Kha nang cao
...

Sheet Item Log
A1: ITEM LOG — Nhat Ky Trang Thai Chi Tiet (Bang 3.1) | Nhap NGAY chuyen trang thai → Cong thuc tu dong tinh
A2: THONG TIN ITEM | H2: DEV PIPELINE (Ngay bat dau tung buoc) | M2: QA PIPELINE (Song song) | Q2: FINAL | S2: TU DONG TINH (CONG THUC)
A3: Ma Item | B3: Ten Hang Muc | C3: Loai | D3: Dev | E3: QA | F3: Reviewer | G3: Gio UT | H3: Detail Design | I3: Review Design | J3: Coding | K3: Review Code | L3: Whitebox | M3: Test Viewpoint | N3: Test Cases | O3: Review TC | P3: Test Execute | Q3: Accept Test | R3: Done | S3: Cycle Time | T3: Lead Time | U3: Trang Thai | V3: Phase Hien Tai
A4: ITM-001 | B4: Bug: Task #1 | C4: Bug | D4: Dev_C | E4: QA_2 | F4: Dev_A | G4: 24 | H4: 46120 | I4: 46122 | J4: 46124 | K4: 46127 | L4: 46129 | M4: 46125 | N4: 46126 | O4: 46128 | P4: 46130 | Q4: 46131 | R4: 46133 | S4: =IF(AND(R4<>"",J4<>""),R4-J4,"") -> 9 | T4: =IF(AND(R4<>"",H4<>""),R4-H4,"") -> 13 | U4: =IF(R4<>"","Done",IF(Q4<>"","Accept Test",IF(P4<>"","Test Execute",IF(O4<>"","Review TC",IF(N4<>"","Test Cases",IF(M4<>"","Test Viewpoint",IF(L4<>"","Whitebox",IF(K4<>"","Review Code",IF(J4<>"","Coding",IF(I4<>"","Review Design",IF(H4<>"","Detail Design","To Do"))))))))))) -> Done | V4: =IF(R4<>"","Done",IF(Q4<>"","Final",IF(OR(P4<>"",O4<>"",N4<>"",M4<>""),"QA",IF(OR(L4<>"",K4<>"",J4<>"",I4<>"",H4<>""),"Dev","Backlog")))) -> Done
A5: ITM-002 | B5: Feature: Task #2 | C5: Feature | D5: Dev_C | E5: QA_2 | F5: Dev_A | G5: 24 | H5: 46121 | I5: 46123 | J5: 46125 | K5: 46129 | L5: 46131 | M5: 46125 | N5: 46126 | O5: 46127 | P5: 46132 | Q5: 46133 | R5: 46134 | S5: =IF(AND(R5<>"",J5<>""),R5-J5,"") -> 9 | T5: =IF(AND(R5<>"",H5<>""),R5-H5,"") -> 13 | U5: =IF(R5<>"","Done",IF(Q5<>"","Accept Test",IF(P5<>"","Test Execute",IF(O5<>"","Review TC",IF(N5<>"","Test Cases",IF(M5<>"","Test Viewpoint",IF(L5<>"","Whitebox",IF(K5<>"","Review Code",IF(J5<>"","Coding",IF(I5<>"","Review Design",IF(H5<>"","Detail Design","To Do"))))))))))) -> Done | V5: =IF(R5<>"","Done",IF(Q5<>"","Final",IF(OR(P5<>"",O5<>"",N5<>"",M5<>""),"QA",IF(OR(L5<>"",K5<>"",J5<>"",I5<>"",H5<>""),"Dev","Backlog")))) -> Done
A6: ITM-003 | B6: Spike: Task #3 | C6: Spike | D6: Dev_B | E6: QA_1 | F6: Dev_A | G6: 8 | H6: 46119 | I6: 46120 | J6: 46122 | K6: 46124 | L6: 46126 | M6: 46123 | N6: 46124 | O6: 46126 | P6: 46128 | Q6: 46131 | R6: 46133 | S6: =IF(AND(R6<>"",J6<>""),R6-J6,"") -> 11 | T6: =IF(AND(R6<>"",H6<>""),R6-H6,"") -> 14 | U6: =IF(R6<>"","Done",IF(Q6<>"","Accept Test",IF(P6<>"","Test Execute",IF(O6<>"","Review TC",IF(N6<>"","Test Cases",IF(M6<>"","Test Viewpoint",IF(L6<>"","Whitebox",IF(K6<>"","Review Code",IF(J6<>"","Coding",IF(I6<>"","Review Design",IF(H6<>"","Detail Design","To Do"))))))))))) -> Done | V6: =IF(R6<>"","Done",IF(Q6<>"","Final",IF(OR(P6<>"",O6<>"",N6<>"",M6<>""),"QA",IF(OR(L6<>"",K6<>"",J6<>"",I6<>"",H6<>""),"Dev","Backlog")))) -> Done
A7: ITM-004 | B7: Bug: Task #4 | C7: Bug | D7: Dev_B | E7: QA_2 | F7: Dev_A | G7: 32 | H7: 46119 | I7: 46121 | J7: 46122 | K7: 46125 | L7: 46126 | M7: 46123 | N7: 46124 | O7: 46126 | P7: 46128 | Q7: 46129 | R7: 46131 | S7: =IF(AND(R7<>"",J7<>""),R7-J7,"") -> 9 | T7: =IF(AND(R7<>"",H7<>""),R7-H7,"") -> 12 | U7: =IF(R7<>"","Done",IF(Q7<>"","Accept Test",IF(P7<>"","Test Execute",IF(O7<>"","Review TC",IF(N7<>"","Test Cases",IF(M7<>"","Test Viewpoint",IF(L7<>"","Whitebox",IF(K7<>"","Review Code",IF(J7<>"","Coding",IF(I7<>"","Review Design",IF(H7<>"","Detail Design","To Do"))))))))))) -> Done | V7: =IF(R7<>"","Done",IF(Q7<>"","Final",IF(OR(P7<>"",O7<>"",N7<>"",M7<>""),"QA",IF(OR(L7<>"",K7<>"",J7<>"",I7<>"",H7<>""),"Dev","Backlog")))) -> Done
A8: ITM-005 | B8: Bug: Task #5 | C8: Bug | D8: Dev_B | E8: QA_2 | F8: Dev_A | G8: 24 | H8: 46121 | I8: 46123 | J8: 46124 | K8: 46127 | L8: 46129 | M8: 46124 | N8: 46125 | O8: 46127 | P8: 46131 | Q8: 46134 | R8: 46136 | S8: =IF(AND(R8<>"",J8<>""),R8-J8,"") -> 12 | T8: =IF(AND(R8<>"",H8<>""),R8-H8,"") -> 15 | U8: =IF(R8<>"","Done",IF(Q8<>"","Accept Test",IF(P8<>"","Test Execute",IF(O8<>"","Review TC",IF(N8<>"","Test Cases",IF(M8<>"","Test Viewpoint",IF(L8<>"","Whitebox",IF(K8<>"","Review Code",IF(J8<>"","Coding",IF(I8<>"","Review Design",IF(H8<>"","Detail Design","To Do"))))))))))) -> Done | V8: =IF(R8<>"","Done",IF(Q8<>"","Final",IF(OR(P8<>"",O8<>"",N8<>"",M8<>""),"QA",IF(OR(L8<>"",K8<>"",J8<>"",I8<>"",H8<>""),"Dev","Backlog")))) -> Done
A9: ITM-006 | B9: Feature: Task #6 | C9: Feature | D9: Dev_A | E9: QA_2 | F9: Dev_B | G9: 16 | H9: 46124 | I9: 46125 | J9: 46127 | K9: 46129 | L9: 46131 | M9: 46127 | N9: 46128 | O9: 46130 | P9: 46132 | Q9: 46133 | R9: 46135 | S9: =IF(AND(R9<>"",J9<>""),R9-J9,"") -> 8 | T9: =IF(AND(R9<>"",H9<>""),R9-H9,"") -> 11 | U9: =IF(R9<>"","Done",IF(Q9<>"","Accept Test",IF(P9<>"","Test Execute",IF(O9<>"","Review TC",IF(N9<>"","Test Cases",IF(M9<>"","Test Viewpoint",IF(L9<>"","Whitebox",IF(K9<>"","Review Code",IF(J9<>"","Coding",IF(I9<>"","Review Design",IF(H9<>"","Detail Design","To Do"))))))))))) -> Done | V9: =IF(R9<>"","Done",IF(Q9<>"","Final",IF(OR(P9<>"",O9<>"",N9<>"",M9<>""),"QA",IF(OR(L9<>"",K9<>"",J9<>"",I9<>"",H9<>""),"Dev","Backlog")))) -> Done
A10: ITM-007 | B10: Feature: Task #7 | C10: Feature | D10: Dev_A | E10: QA_1 | F10: Dev_B | G10: 8 | H10: 46124 | I10: 46125 | J10: 46126 | K10: 46127 | L10: 46128 | M10: 46127 | N10: 46128 | O10: 46130 | P10: 46131 | Q10: 46132 | R10: 46133 | S10: =IF(AND(R10<>"",J10<>""),R10-J10,"") -> 7 | T10: =IF(AND(R10<>"",H10<>""),R10-H10,"") -> 9 | U10: =IF(R10<>"","Done",IF(Q10<>"","Accept Test",IF(P10<>"","Test Execute",IF(O10<>"","Review TC",IF(N10<>"","Test Cases",IF(M10<>"","Test Viewpoint",IF(L10<>"","Whitebox",IF(K10<>"","Review Code",IF(J10<>"","Coding",IF(I10<>"","Review Design",IF(H10<>"","Detail Design","To Do"))))))))))) -> Done | V10: =IF(R10<>"","Done",IF(Q10<>"","Final",IF(OR(P10<>"",O10<>"",N10<>"",M10<>""),"QA",IF(OR(L10<>"",K10<>"",J10<>"",I10<>"",H10<>""),"Dev","Backlog")))) -> Done
A11: ITM-008 | B11: Bug: Task #8 | C11: Bug | D11: Dev_C | E11: QA_2 | F11: Dev_A | G11: 16 | H11: 46125 | I11: 46126 | J11: 46127 | K11: 46129 | L11: 46130 | M11: 46127 | N11: 46128 | O11: 46130 | P11: 46132 | Q11: 46135 | R11: 46136 | S11: =IF(AND(R11<>"",J11<>""),R11-J11,"") -> 9 | T11: =IF(AND(R11<>"",H11<>""),R11-H11,"") -> 11 | U11: =IF(R11<>"","Done",IF(Q11<>"","Accept Test",IF(P11<>"","Test Execute",IF(O11<>"","Review TC",IF(N11<>"","Test Cases",IF(M11<>"","Test Viewpoint",IF(L11<>"","Whitebox",IF(K11<>"","Review Code",IF(J11<>"","Coding",IF(I11<>"","Review Design",IF(H11<>"","Detail Design","To Do"))))))))))) -> Done | V11: =IF(R11<>"","Done",IF(Q11<>"","Final",IF(OR(P11<>"",O11<>"",N11<>"",M11<>""),"QA",IF(OR(L11<>"",K11<>"",J11<>"",I11<>"",H11<>""),"Dev","Backlog")))) -> Done
A12: ITM-009 | B12: Feature: Task #9 | C12: Feature | D12: Dev_C | E12: QA_2 | F12: Dev_A | G12: 12 | H12: 46124 | I12: 46126 | J12: 46127 | K12: 46129 | L12: 46130 | M12: 46127 | N12: 46128 | O12: 46129 | P12: 46132 | Q12: 46134 | R12: 46135 | S12: =IF(AND(R12<>"",J12<>""),R12-J12,"") -> 8 | T12: =IF(AND(R12<>"",H12<>""),R12-H12,"") -> 11 | U12: =IF(R12<>"","Done",IF(Q12<>"","Accept Test",IF(P12<>"","Test Execute",IF(O12<>"","Review TC",IF(N12<>"","Test Cases",IF(M12<>"","Test Viewpoint",IF(L12<>"","Whitebox",IF(K12<>"","Review Code",IF(J12<>"","Coding",IF(I12<>"","Review Design",IF(H12<>"","Detail Design","To Do"))))))))))) -> Done | V12: =IF(R12<>"","Done",IF(Q12<>"","Final",IF(OR(P12<>"",O12<>"",N12<>"",M12<>""),"QA",IF(OR(L12<>"",K12<>"",J12<>"",I12<>"",H12<>""),"Dev","Backlog")))) -> Done
A13: ITM-010 | B13: Feature: Task #10 | C13: Feature | D13: Dev_B | E13: QA_2 | F13: Dev_A | G13: 8 | H13: 46121 | I13: 46123 | J13: 46125 | K13: 46127 | L13: 46129 | M13: 46126 | N13: 46127 | O13: 46128 | P13: 46131 | Q13: 46133 | R13: 46135 | S13: =IF(AND(R13<>"",J13<>""),R13-J13,"") -> 10 | T13: =IF(AND(R13<>"",H13<>""),R13-H13,"") -> 14 | U13: =IF(R13<>"","Done",IF(Q13<>"","Accept Test",IF(P13<>"","Test Execute",IF(O13<>"","Review TC",IF(N13<>"","Test Cases",IF(M13<>"","Test Viewpoint",IF(L13<>"","Whitebox",IF(K13<>"","Review Code",IF(J13<>"","Coding",IF(I13<>"","Review Design",IF(H13<>"","Detail Design","To Do"))))))))))) -> Done | V13: =IF(R13<>"","Done",IF(Q13<>"","Final",IF(OR(P13<>"",O13<>"",N13<>"",M13<>""),"QA",IF(OR(L13<>"",K13<>"",J13<>"",I13<>"",H13<>""),"Dev","Backlog")))) -> Done
A14: ITM-011 | B14: Spike: Task #11 | C14: Spike | D14: Dev_A | E14: QA_1 | F14: Dev_B | G14: 4 | H14: 46127 | I14: 46129 | J14: 46131 | K14: 46132 | L14: 46133 | M14: 46132 | N14: 46133 | O14: 46134 | P14: 46135 | Q14: 46136 | R14: 46137 | S14: =IF(AND(R14<>"",J14<>""),R14-J14,"") -> 6 | T14: =IF(AND(R14<>"",H14<>""),R14-H14,"") -> 10 | U14: =IF(R14<>"","Done",IF(Q14<>"","Accept Test",IF(P14<>"","Test Execute",IF(O14<>"","Review TC",IF(N14<>"","Test Cases",IF(M14<>"","Test Viewpoint",IF(L14<>"","Whitebox",IF(K14<>"","Review Code",IF(J14<>"","Coding",IF(I14<>"","Review Design",IF(H14<>"","Detail Design","To Do"))))))))))) -> Done | V14: =IF(R14<>"","Done",IF(Q14<>"","Final",IF(OR(P14<>"",O14<>"",N14<>"",M14<>""),"QA",IF(OR(L14<>"",K14<>"",J14<>"",I14<>"",H14<>""),"Dev","Backlog")))) -> Done
A15: ITM-012 | B15: Feature: Task #12 | C15: Feature | D15: Dev_C | E15: QA_1 | F15: Dev_A | G15: 8 | H15: 46127 | I15: 46128 | J15: 46130 | K15: 46132 | L15: 46133 | M15: 46130 | N15: 46131 | O15: 46132 | P15: 46134 | Q15: 46135 | R15: 46136 | S15: =IF(AND(R15<>"",J15<>""),R15-J15,"") -> 6 | T15: =IF(AND(R15<>"",H15<>""),R15-H15,"") -> 9 | U15: =IF(R15<>"","Done",IF(Q15<>"","Accept Test",IF(P15<>"","Test Execute",IF(O15<>"","Review TC",IF(N15<>"","Test Cases",IF(M15<>"","Test Viewpoint",IF(L15<>"","Whitebox",IF(K15<>"","Review Code",IF(J15<>"","Coding",IF(I15<>"","Review Design",IF(H15<>"","Detail Design","To Do"))))))))))) -> Done | V15: =IF(R15<>"","Done",IF(Q15<>"","Final",IF(OR(P15<>"",O15<>"",N15<>"",M15<>""),"QA",IF(OR(L15<>"",K15<>"",J15<>"",I15<>"",H15<>""),"Dev","Backlog")))) -> Done
... A39: ITM-036 | B39: Tech Debt: Task #36 | C39: Tech Debt | D39: Dev_B | E39: QA_2 | F39: Dev_A | G39: 16 | H39: 46142 | I39: 46144 | J39: 46145 | K39: 46148 | L39: 46150 | M39: 46146 | N39: 46147 | O39: 46148 | P39: 46152 | Q39: 46155 | R39: 46157 | S39: =IF(AND(R39<>"",J39<>""),R39-J39,"") -> 12 | T39: =IF(AND(R39<>"",H39<>""),R39-H39,"") -> 15 | U39: =IF(R39<>"","Done",IF(Q39<>"","Accept Test",IF(P39<>"","Test Execute",IF(O39<>"","Review TC",IF(N39<>"","Test Cases",IF(M39<>"","Test Viewpoint",IF(L39<>"","Whitebox",IF(K39<>"","Review Code",IF(J39<>"","Coding",IF(I39<>"","Review Design",IF(H39<>"","Detail Design","To Do"))))))))))) -> Done | V39: =IF(R39<>"","Done",IF(Q39<>"","Final",IF(OR(P39<>"",O39<>"",N39<>"",M39<>""),"QA",IF(OR(L39<>"",K39<>"",J39<>"",I39<>"",H39<>""),"Dev","Backlog")))) -> Done
A40: ITM-037 | B40: Tech Debt: Task #37 | C40: Tech Debt | D40: Dev_C | E40: QA_1 | F40: Dev_A | G40: 24 | H40: 46141 | I40: 46143 | J40: 46144 | K40: 46147 | L40: 46148 | M40: 46145 | N40: 46146 | O40: 46148 | P40: 46149 | S40: =IF(AND(R40<>"",J40<>""),R40-J40,"") | T40: =IF(AND(R40<>"",H40<>""),R40-H40,"") | U40: =IF(R40<>"","Done",IF(Q40<>"","Accept Test",IF(P40<>"","Test Execute",IF(O40<>"","Review TC",IF(N40<>"","Test Cases",IF(M40<>"","Test Viewpoint",IF(L40<>"","Whitebox",IF(K40<>"","Review Code",IF(J40<>"","Coding",IF(I40<>"","Review Design",IF(H40<>"","Detail Design","To Do"))))))))))) -> Test Execute | V40: =IF(R40<>"","Done",IF(Q40<>"","Final",IF(OR(P40<>"",O40<>"",N40<>"",M40<>""),"QA",IF(OR(L40<>"",K40<>"",J40<>"",I40<>"",H40<>""),"Dev","Backlog")))) -> QA
A41: ITM-038 | B41: Bug: Task #38 | C41: Bug | D41: Dev_B | E41: QA_2 | F41: Dev_A | G41: 32 | H41: 46140 | I41: 46141 | J41: 46142 | K41: 46147 | L41: 46148 | M41: 46143 | N41: 46144 | S41: =IF(AND(R41<>"",J41<>""),R41-J41,"") | T41: =IF(AND(R41<>"",H41<>""),R41-H41,"") | U41: =IF(R41<>"","Done",IF(Q41<>"","Accept Test",IF(P41<>"","Test Execute",IF(O41<>"","Review TC",IF(N41<>"","Test Cases",IF(M41<>"","Test Viewpoint",IF(L41<>"","Whitebox",IF(K41<>"","Review Code",IF(J41<>"","Coding",IF(I41<>"","Review Design",IF(H41<>"","Detail Design","To Do"))))))))))) -> Test Cases | V41: =IF(R41<>"","Done",IF(Q41<>"","Final",IF(OR(P41<>"",O41<>"",N41<>"",M41<>""),"QA",IF(OR(L41<>"",K41<>"",J41<>"",I41<>"",H41<>""),"Dev","Backlog")))) -> QA
A42: ITM-039 | B42: Bug: Task #39 | C42: Bug | D42: Dev_C | E42: QA_2 | F42: Dev_A | G42: 24 | H42: 46141 | I42: 46142 | J42: 46143 | K42: 46145 | L42: 46146 | M42: 46143 | N42: 46144 | S42: =IF(AND(R42<>"",J42<>""),R42-J42,"") | T42: =IF(AND(R42<>"",H42<>""),R42-H42,"") | U42: =IF(R42<>"","Done",IF(Q42<>"","Accept Test",IF(P42<>"","Test Execute",IF(O42<>"","Review TC",IF(N42<>"","Test Cases",IF(M42<>"","Test Viewpoint",IF(L42<>"","Whitebox",IF(K42<>"","Review Code",IF(J42<>"","Coding",IF(I42<>"","Review Design",IF(H42<>"","Detail Design","To Do"))))))))))) -> Test Cases | V42: =IF(R42<>"","Done",IF(Q42<>"","Final",IF(OR(P42<>"",O42<>"",N42<>"",M42<>""),"QA",IF(OR(L42<>"",K42<>"",J42<>"",I42<>"",H42<>""),"Dev","Backlog")))) -> QA
A43: ITM-040 | B43: Tech Debt: Task #40 | C43: Tech Debt | D43: Dev_C | E43: QA_2 | F43: Dev_A | G43: 8 | H43: 46143 | I43: 46144 | J43: 46145 | K43: 46146 | L43: 46148 | M43: 46145 | N43: 46146 | O43: 46147 | P43: 46150 | Q43: 46153 | S43: =IF(AND(R43<>"",J43<>""),R43-J43,"") | T43: =IF(AND(R43<>"",H43<>""),R43-H43,"") | U43: =IF(R43<>"","Done",IF(Q43<>"","Accept Test",IF(P43<>"","Test Execute",IF(O43<>"","Review TC",IF(N43<>"","Test Cases",IF(M43<>"","Test Viewpoint",IF(L43<>"","Whitebox",IF(K43<>"","Review Code",IF(J43<>"","Coding",IF(I43<>"","Review Design",IF(H43<>"","Detail Design","To Do"))))))))))) -> Accept Test | V43: =IF(R43<>"","Done",IF(Q43<>"","Final",IF(OR(P43<>"",O43<>"",N43<>"",M43<>""),"QA",IF(OR(L43<>"",K43<>"",J43<>"",I43<>"",H43<>""),"Dev","Backlog")))) -> Final
A44: ITM-041 | B44: Tech Debt: Task #41 | C44: Tech Debt | D44: Dev_C | E44: QA_2 | F44: Dev_A | G44: 24 | H44: 46144 | I44: 46146 | J44: 46148 | K44: 46151 | L44: 46153 | S44: =IF(AND(R44<>"",J44<>""),R44-J44,"") | T44: =IF(AND(R44<>"",H44<>""),R44-H44,"") | U44: =IF(R44<>"","Done",IF(Q44<>"","Accept Test",IF(P44<>"","Test Execute",IF(O44<>"","Review TC",IF(N44<>"","Test Cases",IF(M44<>"","Test Viewpoint",IF(L44<>"","Whitebox",IF(K44<>"","Review Code",IF(J44<>"","Coding",IF(I44<>"","Review Design",IF(H44<>"","Detail Design","To Do"))))))))))) -> Whitebox | V44: =IF(R44<>"","Done",IF(Q44<>"","Final",IF(OR(P44<>"",O44<>"",N44<>"",M44<>""),"QA",IF(OR(L44<>"",K44<>"",J44<>"",I44<>"",H44<>""),"Dev","Backlog")))) -> Dev
A45: ITM-042 | B45: Feature: Task #42 | C45: Feature | D45: Dev_B | E45: QA_2 | F45: Dev_A | G45: 8 | H45: 46144 | I45: 46145 | J45: 46147 | K45: 46148 | L45: 46150 | M45: 46147 | N45: 46148 | S45: =IF(AND(R45<>"",J45<>""),R45-J45,"") | T45: =IF(AND(R45<>"",H45<>""),R45-H45,"") | U45: =IF(R45<>"","Done",IF(Q45<>"","Accept Test",IF(P45<>"","Test Execute",IF(O45<>"","Review TC",IF(N45<>"","Test Cases",IF(M45<>"","Test Viewpoint",IF(L45<>"","Whitebox",IF(K45<>"","Review Code",IF(J45<>"","Coding",IF(I45<>"","Review Design",IF(H45<>"","Detail Design","To Do"))))))))))) -> Test Cases | V45: =IF(R45<>"","Done",IF(Q45<>"","Final",IF(OR(P45<>"",O45<>"",N45<>"",M45<>""),"QA",IF(OR(L45<>"",K45<>"",J45<>"",I45<>"",H45<>""),"Dev","Backlog")))) -> QA
A46: ITM-043 | B46: Feature: Task #43 | C46: Feature | D46: Dev_C | E46: QA_1 | F46: Dev_A | G46: 16 | H46: 46146 | I46: 46148 | J46: 46150 | K46: 46152 | L46: 46154 | M46: 46150 | N46: 46151 | S46: =IF(AND(R46<>"",J46<>""),R46-J46,"") | T46: =IF(AND(R46<>"",H46<>""),R46-H46,"") | U46: =IF(R46<>"","Done",IF(Q46<>"","Accept Test",IF(P46<>"","Test Execute",IF(O46<>"","Review TC",IF(N46<>"","Test Cases",IF(M46<>"","Test Viewpoint",IF(L46<>"","Whitebox",IF(K46<>"","Review Code",IF(J46<>"","Coding",IF(I46<>"","Review Design",IF(H46<>"","Detail Design","To Do"))))))))))) -> Test Cases | V46: =IF(R46<>"","Done",IF(Q46<>"","Final",IF(OR(P46<>"",O46<>"",N46<>"",M46<>""),"QA",IF(OR(L46<>"",K46<>"",J46<>"",I46<>"",H46<>""),"Dev","Backlog")))) -> QA
A47: ITM-044 | B47: Tech Debt: Task #44 | C47: Tech Debt | D47: Dev_C | E47: QA_2 | F47: Dev_A | G47: 32 | H47: 46144 | I47: 46145 | J47: 46146 | K47: 46150 | L47: 46151 | M47: 46147 | N47: 46148 | S47: =IF(AND(R47<>"",J47<>""),R47-J47,"") | T47: =IF(AND(R47<>"",H47<>""),R47-H47,"") | U47: =IF(R47<>"","Done",IF(Q47<>"","Accept Test",IF(P47<>"","Test Execute",IF(O47<>"","Review TC",IF(N47<>"","Test Cases",IF(M47<>"","Test Viewpoint",IF(L47<>"","Whitebox",IF(K47<>"","Review Code",IF(J47<>"","Coding",IF(I47<>"","Review Design",IF(H47<>"","Detail Design","To Do"))))))))))) -> Test Cases | V47: =IF(R47<>"","Done",IF(Q47<>"","Final",IF(OR(P47<>"",O47<>"",N47<>"",M47<>""),"QA",IF(OR(L47<>"",K47<>"",J47<>"",I47<>"",H47<>""),"Dev","Backlog")))) -> QA
A48: ITM-045 | B48: Spike: Task #45 | C48: Spike | D48: Dev_A | E48: QA_2 | F48: Dev_B | G48: 8 | H48: 46145 | I48: 46147 | J48: 46148 | K48: 46149 | L48: 46150 | M48: 46148 | N48: 46149 | S48: =IF(AND(R48<>"",J48<>""),R48-J48,"") | T48: =IF(AND(R48<>"",H48<>""),R48-H48,"") | U48: =IF(R48<>"","Done",IF(Q48<>"","Accept Test",IF(P48<>"","Test Execute",IF(O48<>"","Review TC",IF(N48<>"","Test Cases",IF(M48<>"","Test Viewpoint",IF(L48<>"","Whitebox",IF(K48<>"","Review Code",IF(J48<>"","Coding",IF(I48<>"","Review Design",IF(H48<>"","Detail Design","To Do"))))))))))) -> Test Cases | V48: =IF(R48<>"","Done",IF(Q48<>"","Final",IF(OR(P48<>"",O48<>"",N48<>"",M48<>""),"QA",IF(OR(L48<>"",K48<>"",J48<>"",I48<>"",H48<>""),"Dev","Backlog")))) -> QA
A49: ITM-046 | B49: Bug: Task #46 | C49: Bug | D49: Dev_B | E49: QA_1 | F49: Dev_A | G49: 32 | H49: 46146 | I49: 46148 | J49: 46149 | K49: 46153 | L49: 46154 | M49: 46149 | N49: 46150 | O49: 46151 | P49: 46155 | S49: =IF(AND(R49<>"",J49<>""),R49-J49,"") | T49: =IF(AND(R49<>"",H49<>""),R49-H49,"") | U49: =IF(R49<>"","Done",IF(Q49<>"","Accept Test",IF(P49<>"","Test Execute",IF(O49<>"","Review TC",IF(N49<>"","Test Cases",IF(M49<>"","Test Viewpoint",IF(L49<>"","Whitebox",IF(K49<>"","Review Code",IF(J49<>"","Coding",IF(I49<>"","Review Design",IF(H49<>"","Detail Design","To Do"))))))))))) -> Test Execute | V49: =IF(R49<>"","Done",IF(Q49<>"","Final",IF(OR(P49<>"",O49<>"",N49<>"",M49<>""),"QA",IF(OR(L49<>"",K49<>"",J49<>"",I49<>"",H49<>""),"Dev","Backlog")))) -> QA
A50: ITM-047 | B50: Feature: Task #47 | C50: Feature | D50: Dev_C | E50: QA_2 | F50: Dev_A | G50: 24 | H50: 46147 | I50: 46149 | J50: 46150 | K50: 46154 | L50: 46156 | S50: =IF(AND(R50<>"",J50<>""),R50-J50,"") | T50: =IF(AND(R50<>"",H50<>""),R50-H50,"") | U50: =IF(R50<>"","Done",IF(Q50<>"","Accept Test",IF(P50<>"","Test Execute",IF(O50<>"","Review TC",IF(N50<>"","Test Cases",IF(M50<>"","Test Viewpoint",IF(L50<>"","Whitebox",IF(K50<>"","Review Code",IF(J50<>"","Coding",IF(I50<>"","Review Design",IF(H50<>"","Detail Design","To Do"))))))))))) -> Whitebox | V50: =IF(R50<>"","Done",IF(Q50<>"","Final",IF(OR(P50<>"",O50<>"",N50<>"",M50<>""),"QA",IF(OR(L50<>"",K50<>"",J50<>"",I50<>"",H50<>""),"Dev","Backlog")))) -> Dev
A51: ITM-048 | B51: Feature: Task #48 | C51: Feature | D51: Dev_C | E51: QA_1 | F51: Dev_A | G51: 24 | H51: 46146 | I51: 46147 | J51: 46148 | K51: 46151 | S51: =IF(AND(R51<>"",J51<>""),R51-J51,"") | T51: =IF(AND(R51<>"",H51<>""),R51-H51,"") | U51: =IF(R51<>"","Done",IF(Q51<>"","Accept Test",IF(P51<>"","Test Execute",IF(O51<>"","Review TC",IF(N51<>"","Test Cases",IF(M51<>"","Test Viewpoint",IF(L51<>"","Whitebox",IF(K51<>"","Review Code",IF(J51<>"","Coding",IF(I51<>"","Review Design",IF(H51<>"","Detail Design","To Do"))))))))))) -> Review Code | V51: =IF(R51<>"","Done",IF(Q51<>"","Final",IF(OR(P51<>"",O51<>"",N51<>"",M51<>""),"QA",IF(OR(L51<>"",K51<>"",J51<>"",I51<>"",H51<>""),"Dev","Backlog")))) -> Dev
A53: THONG KE TU DONG (TAT CA LA CONG THUC)
A54: Tong Items | F54: =COUNTA(A4:A51) -> 48
A55: Items Done | F55: =COUNTIF(U4:U51,"Done") -> 36
A56: Items Dang Dev | F56: =COUNTIF(V4:V51,"Dev") -> 3
A57: Items Dang QA | F57: =COUNTIF(V4:V51,"QA") -> 8
A58: Items Dang Final | F58: =COUNTIF(V4:V51,"Final") -> 1
A59: Items Backlog | F59: =COUNTIF(V4:V51,"Backlog") -> 0
A60: Avg Cycle Time | F60: =IFERROR(AVERAGEIF(S4:S51,"<>","S4:S51"),"")
A61: Max Cycle Time | F61: =MAX(S4:S51) -> 12
A62: Min Cycle Time | F62: =MIN(S4:S51) -> 6
A63: Avg Lead Time | F63: =IFERROR(AVERAGEIF(T4:T51,">0"),"") -> 11.833333
A64: Tong Gio Estimate | F64: =SUM(G4:G51) -> 888
...

Sheet Daily WIP
A1: DAILY WIP TRACKER — Theo Doi HANG NGAY | PM dien cuoi moi ngay lam viec
A2: Huong dan: Moi ngay cuoi gio, dem so items o tung stage va dien vao. Cong thuc tu dong tinh WIP, status, canh bao.
C3: DEV PIPELINE | H3: QA PIPELINE | N3: TU DONG (CONG THUC)
A4: Ngay | B4: Thu | C4: Detail Design | D4: Rev Design | E4: Coding | F4: Rev Code | G4: Whitebox | H4: Test VP | I4: Test Cases | J4: Rev TC | K4: Test Exec | L4: Accept Test | M4: Done | N4: WIP Dev | O4: WIP QA | P4: WIP Total
A5: LIMIT | C5: -- | D5: 2 | E5: 3 | F5: 2 | G5: 2 | H5: -- | I5: 3 | J5: 2 | K5: 3 | L5: 2 | M5: --
A6: 46118 | B6: T2 | C6: 4 | D6: 2 | E6: 2 | F6: 0 | G6: 0 | H6: 0 | I6: 1 | J6: 2 | K6: 2 | L6: 0 | M6: 0 | N6: =SUM(C6:G6) -> 8 | O6: =SUM(H6:K6) -> 5 | P6: =N6+O6+L6 -> 13
A7: 46119 | B7: T3 | C7: 3 | D7: 0 | E7: 3 | F7: 1 | G7: 2 | H7: 1 | I7: 2 | J7: 1 | K7: 3 | L7: 0 | M7: 2 | N7: =SUM(C7:G7) -> 9 | O7: =SUM(H7:K7) -> 7 | P7: =N7+O7+L7 -> 16
A8: 46120 | B8: T4 | C8: 3 | D8: 2 | E8: 3 | F8: 1 | G8: 2 | H8: 2 | I8: 2 | J8: 0 | K8: 1 | L8: 2 | M8: 4 | N8: =SUM(C8:G8) -> 11 | O8: =SUM(H8:K8) -> 5 | P8: =N8+O8+L8 -> 18
A9: 46121 | B9: T5 | C9: 2 | D9: 0 | E9: 1 | F9: 1 | G9: 2 | H9: 2 | I9: 3 | J9: 2 | K9: 1 | L9: 0 | M9: 6 | N9: =SUM(C9:G9) -> 6 | O9: =SUM(H9:K9) -> 8 | P9: =N9+O9+L9 -> 14
A10: 46122 | B10: T6 | C10: 2 | D10: 0 | E10: 3 | F10: 1 | G10: 0 | H10: 1 | I10: 1 | J10: 2 | K10: 1 | L10: 2 | M10: 8 | N10: =SUM(C10:G10) -> 6 | O10: =SUM(H10:K10) -> 5 | P10: =N10+O10+L10 -> 13
A11: 46125 | B11: T2 | C11: 3 | D11: 1 | E11: 3 | F11: 1 | G11: 1 | H11: 0 | I11: 2 | J11: 2 | K11: 2 | L11: 1 | M11: 10 | N11: =SUM(C11:G11) -> 9 | O11: =SUM(H11:K11) -> 6 | P11: =N11+O11+L11 -> 16
A12: 46126 | B12: T3 | C12: 3 | D12: 1 | E12: 1 | F12: 0 | G12: 0 | H12: 2 | I12: 1 | J12: 1 | K12: 2 | L12: 1 | M12: 12 | N12: =SUM(C12:G12) -> 5 | O12: =SUM(H12:K12) -> 6 | P12: =N12+O12+L12 -> 12
A13: 46127 | B13: T4 | C13: 1 | D13: 2 | E13: 3 | F13: 2 | G13: 1 | H13: 1 | I13: 3 | J13: 0 | K13: 2 | L13: 1 | M13: 14 | N13: =SUM(C13:G13) -> 9 | O13: =SUM(H13:K13) -> 6 | P13: =N13+O13+L13 -> 16
A14: 46128 | B14: T5 | C14: 3 | D14: 2 | E14: 3 | F14: 2 | G14: 0 | H14: 1 | I14: 2 | J14: 0 | K14: 1 | L14: 2 | M14: 16 | N14: =SUM(C14:G14) -> 10 | O14: =SUM(H14:K14) -> 4 | P14: =N14+O14+L14 -> 16
A15: 46129 | B15: T6 | C15: 1 | D15: 0 | E15: 3 | F15: 1 | G15: 2 | H15: 0 | I15: 2 | J15: 2 | K15: 3 | L15: 1 | M15: 18 | N15: =SUM(C15:G15) -> 7 | O15: =SUM(H15:K15) -> 7 | P15: =N15+O15+L15 -> 15
A16: 46132 | B16: T2 | C16: 4 | D16: 2 | E16: 1 | F16: 0 | G16: 1 | H16: 0 | I16: 1 | J16: 0 | K16: 2 | L16: 0 | M16: 20 | N16: =SUM(C16:G16) -> 8 | O16: =SUM(H16:K16) -> 3 | P16: =N16+O16+L16 -> 11
A17: 46133 | B17: T3 | C17: 2 | D17: 2 | E17: 2 | F17: 0 | G17: 0 | H17: 2 | I17: 1 | J17: 2 | K17: 3 | L17: 0 | M17: 22 | N17: =SUM(C17:G17) -> 6 | O17: =SUM(H17:K17) -> 8 | P17: =N17+O17+L17 -> 14
... A30: 46150 | B30: T6 | C30: 2 | D30: 1 | E30: 1 | F30: 2 | G30: 1 | H30: 0 | I30: 3 | J30: 1 | K30: 2 | L30: 0 | M30: 36 | N30: =SUM(C30:G30) -> 7 | O30: =SUM(H30:K30) -> 6 | P30: =N30+O30+L30 -> 13
A32: CANH BAO TU DONG (CONG THUC)
A33: Rev Design vuot limit? | D33: =IF(MAX(D6:D30)>2,"⚠ VUOT — Max: "&MAX(D6:D30),"OK") -> OK | G33: Review Design WIP > 2
A34: Rev Code vuot limit? | D34: =IF(MAX(F6:F30)>2,"⚠ VUOT — Max: "&MAX(F6:F30),"OK") -> OK | G34: Review Code WIP > 2 = bottleneck
A35: Coding vuot limit? | D35: =IF(MAX(E6:E30)>3,"⚠ VUOT — Max: "&MAX(E6:E30),"OK") -> OK | G35: Coding WIP > 3
A36: Rev TC vuot limit? | D36: =IF(MAX(J6:J30)>2,"⚠ VUOT — Max: "&MAX(J6:J30),"OK") -> OK | G36: Review TC WIP > 2
A37: Total WIP vuot 9? | D37: =IF(MAX(P6:P30)>9,"⚠ VUOT — Max: "&MAX(P6:P30),"OK") -> ⚠ VUOT — Max: 20 | G37: Tong WIP > 9 = flow nghen
A38: Avg WIP/ngay | D38: =AVERAGE(P6:P30) -> 14.24 | G38: Nen < 9 de flow on dinh

Sheet Weekly Data
A1: DU LIEU TONG HOP THEO TUAN | PM cap nhat moi Thu Sau | 5 BIEU DO tu dong
A2: Cot A-H: NHAP TAY | Cot I tro di: TAT CA LA CONG THUC TU DONG | Tuong thich Google Sheets
C3: NHAP: WIP CUOI TUAN | F3: NHAP: KET QUA TUAN | I3: TU DONG TINH (CONG THUC — KHONG SUA)
A4: Tuan | B4: Ngay Thu 6 | C4: WIP Dev | D4: WIP QA | E4: WIP Final | F4: Items Done (tuan nay) | G4: Gio Done (tuan nay) | H4: Items Done Tich Luy | I4: WIP Total | J4: Items Con Lai | K4: Best Case | L4: Worst Case | M4: Throughput Avg (4w) | N4: Delta TP vs Prev | O4: Gio Con Lai | P4: % Done Items | Q4: % Done Gio | R4: Status | S4: WIP Limit(9)
A5: W01 | B5: 46122 | C5: 4 | D5: 2 | E5: 0 | F5: 6 | G5: 108 | H5: 7 | I5: =C5+D5+E5 -> 6 | J5: =48-H5 -> 41 | K5: =MAX(0,48-(48/10)*1) -> 43.2 | L5: =MAX(0,48-48*POWER(1/(10*1.2),1.3)) -> 46.101959 | M5: =AVERAGE(F5:F5) -> 6 | N5: 0 | O5: =768-SUM(G5:G5) -> 660 | P5: =H5/48 -> 0.14583333 | Q5: =SUM(G5:G5)/768 -> 0.140625 | R5: =IF(J5<=K5,"Nhanh",IF(J5<=L5,"OK","CHAM")) -> Nhanh | S5: 9
A6: W02 | B6: 46129 | C6: 3 | D6: 3 | E6: 2 | F6: 7 | G6: 98 | H6: =H5+F6 -> 14 | I6: =C6+D6+E6 -> 8 | J6: =48-H6 -> 34 | K6: =MAX(0,48-(48/10)*2) -> 38.4 | L6: =MAX(0,48-48*POWER(2/(10*1.2),1.3)) -> 43.326475 | M6: =AVERAGE(F5:F6) -> 6.5 | N6: =F6-F5 -> 1 | O6: =768-SUM(G5:G6) -> 562 | P6: =H6/48 -> 0.29166667 | Q6: =SUM(G5:G6)/768 -> 0.26822917 | R6: =IF(J6<=K6,"Nhanh",IF(J6<=L6,"OK","CHAM")) -> Nhanh | S6: 9
A7: W03 | B7: 46136 | C7: 4 | D7: 4 | E7: 0 | F7: 7 | G7: 119 | H7: =H6+F7 -> 21 | I7: =C7+D7+E7 -> 8 | J7: =48-H7 -> 27 | K7: =MAX(0,48-(48/10)*3) -> 33.6 | L7: =MAX(0,48-48*POWER(3/(10*1.2),1.3)) -> 40.082953 | M7: =AVERAGE(F5:F7) -> 6.6666667 | N7: =F7-F6 -> 0 | O7: =768-SUM(G5:G7) -> 443 | P7: =H7/48 -> 0.4375 | Q7: =SUM(G5:G7)/768 -> 0.42317708 | R7: =IF(J7<=K7,"Nhanh",IF(J7<=L7,"OK","CHAM")) -> Nhanh | S7: 9
A8: W04 | B8: 46143 | C8: 4 | D8: 3 | E8: 0 | F8: 3 | G8: 51 | H8: =H7+F8 -> 24 | I8: =C8+D8+E8 -> 7 | J8: =48-H8 -> 24 | K8: =MAX(0,48-(48/10)*4) -> 28.8 | L8: =MAX(0,48-48*POWER(4/(10*1.2),1.3)) -> 36.492431 | M8: =AVERAGE(F5:F8) -> 5.75 | N8: =F8-F7 -> -4 | O8: =768-SUM(G5:G8) -> 392 | P8: =H8/48 -> 0.5 | Q8: =SUM(G5:G8)/768 -> 0.48958333 | R8: =IF(J8<=K8,"Nhanh",IF(J8<=L8,"OK","CHAM")) -> Nhanh | S8: 9
A9: W05 | B9: 46150 | C9: 4 | D9: 3 | E9: 2 | F9: 4 | G9: 68 | H9: =H8+F9 -> 28 | I9: =C9+D9+E9 -> 9 | J9: =48-H9 -> 20 | K9: =MAX(0,48-(48/10)*5) -> 24 | L9: =MAX(0,48-48*POWER(5/(10*1.2),1.3)) -> 32.619636 | M9: =AVERAGE(F6:F9) -> 5.25 | N9: =F9-F8 -> 1 | O9: =768-SUM(G5:G9) -> 324 | P9: =H9/48 -> 0.58333333 | Q9: =SUM(G5:G9)/768 -> 0.578125 | R9: =IF(J9<=K9,"Nhanh",IF(J9<=L9,"OK","CHAM")) -> Nhanh | S9: 9
A10: W06 | B10: 46157 | C10: 3 | D10: 3 | E10: 0 | F10: 8 | G10: 152 | H10: =H9+F10 -> 36 | I10: =C10+D10+E10 -> 6 | J10: =48-H10 -> 12 | K10: =MAX(0,48-(48/10)*6) -> 19.2 | L10: =MAX(0,48-48*POWER(6/(10*1.2),1.3)) -> 28.505942 | M10: =AVERAGE(F7:F10) -> 5.5 | N10: =F10-F9 -> 4 | O10: =768-SUM(G5:G10) -> 172 | P10: =H10/48 -> 0.75 | Q10: =SUM(G5:G10)/768 -> 0.77604167 | R10: =IF(J10<=K10,"Nhanh",IF(J10<=L10,"OK","CHAM")) -> Nhanh | S10: 9
A11: W07 | B11: 46164 | C11: 5 | D11: 2 | E11: 2 | F11: 8 | G11: 96 | H11: =H10+F11 -> 44 | I11: =C11+D11+E11 -> 9 | J11: =48-H11 -> 4 | K11: =MAX(0,48-(48/10)*7) -> 14.4 | L11: =MAX(0,48-48*POWER(7/(10*1.2),1.3)) -> 24.180476 | M11: =AVERAGE(F8:F11) -> 5.75 | N11: =F11-F10 -> 0 | O11: =768-SUM(G5:G11) -> 76 | P11: =H11/48 -> 0.91666667 | Q11: =SUM(G5:G11)/768 -> 0.90104167 | R11: =IF(J11<=K11,"Nhanh",IF(J11<=L11,"OK","CHAM")) -> Nhanh | S11: 9
A12: W08 | B12: 46171 | C12: 4 | D12: 3 | E12: 2 | F12: 7 | G12: 84 | H12: =H11+F12 -> 51 | I12: =C12+D12+E12 -> 9 | J12: =48-H12 -> -3 | K12: =MAX(0,48-(48/10)*8) -> 9.6 | L12: =MAX(0,48-48*POWER(8/(10*1.2),1.3)) -> 19.66504 | M12: =AVERAGE(F9:F12) -> 6.75 | N12: =F12-F11 -> -1 | O12: =768-SUM(G5:G12) -> -8 | P12: =H12/48 -> 1.0625 | Q12: =SUM(G5:G12)/768 -> 1.0104167 | R12: =IF(J12<=K12,"Nhanh",IF(J12<=L12,"OK","CHAM")) -> Nhanh | S12: 9
A13: W09 | B13: 46178 | C13: 4 | D13: 4 | E13: 1 | F13: 4 | G13: 80 | H13: =H12+F13 -> 55 | I13: =C13+D13+E13 -> 9 | J13: =48-H13 -> -7 | K13: =MAX(0,48-(48/10)*9) -> 4.8 | L13: =MAX(0,48-48*POWER(9/(10*1.2),1.3)) -> 14.976669 | M13: =AVERAGE(F10:F13) -> 6.75 | N13: =F13-F12 -> -3 | O13: =768-SUM(G5:G13) -> -88 | P13: =H13/48 -> 1.1458333 | Q13: =SUM(G5:G13)/768 -> 1.1145833 | R13: =IF(J13<=K13,"Nhanh",IF(J13<=L13,"OK","CHAM")) -> Nhanh | S13: 9
A14: W10 | B14: 46185 | C14: 4 | D14: 3 | E14: 1 | F14: 3 | G14: 57 | H14: =H13+F14 -> 58 | I14: =C14+D14+E14 -> 8 | J14: =48-H14 -> -10 | K14: =MAX(0,48-(48/10)*10) -> 0 | L14: =MAX(0,48-48*POWER(10/(10*1.2),1.3)) -> 10.129101 | M14: =AVERAGE(F11:F14) -> 5.5 | N14: =F14-F13 -> -1 | O14: =768-SUM(G5:G14) -> -145 | P14: =H14/48 -> 1.2083333 | Q14: =SUM(G5:G14)/768 -> 1.1888021 | R14: =IF(J14<=K14,"Nhanh",IF(J14<=L14,"OK","CHAM")) -> Nhanh | S14: 9

Sheet Cycle Time
A1: CYCLE TIME ANALYSIS | Tinh tu Item Log bang cong thuc
A3: PERCENTILE (CONG THUC TU 'Item Log')
A4: Metric | B4: Value (ngay)
A5: P50 (Median) | D5: =MEDIAN('Item Log'!S4:S51) -> 9
A6: P70 | D6: =PERCENTILE('Item Log'!S4:S51,0.7) -> 9
A7: P85 | D7: =PERCENTILE('Item Log'!S4:S51,0.85) -> 10.75
A8: P95 | D8: =PERCENTILE('Item Log'!S4:S51,0.95) -> 12
A9: Average | D9: =AVERAGEIF('Item Log'!S4:S51,">0") -> 8.8333333
A10: Max | D10: =MAX('Item Log'!S4:S51) -> 12
A11: Min | D11: =MIN(IF('Item Log'!S4:S51>0,'Item Log'!S4:S51)) -> 6
A13: CYCLE TIME THEO LOAI ITEM (CONG THUC)
A14: Loai | B14: Count | C14: Avg CT | D14: P85 | E14: Min CT | F14: Max CT
A15: Feature | B15: =COUNTIFS('Item Log'!C4:C51,A15,'Item Log'!S4:S51,">0") -> 20 | C15: =IFERROR(AVERAGEIFS('Item Log'!S4:S51,'Item Log'!C4:C51,A15,'Item Log'!S4:S51,">0"),"") -> 8.75 | D15: =IFERROR(percentile.inc(IF('Item Log'!C4:C51=A15,'Item Log'!S4:S51),0.85),"") | E15: =IFERROR(minifs('Item Log'!S4:S51,'Item Log'!C4:C51,A15,'Item Log'!S4:S51,">0"),"") | F15: =IFERROR(maxifs('Item Log'!S4:S51,'Item Log'!C4:C51,A15,'Item Log'!S4:S51,">0"),"")
A16: Bug | B16: =COUNTIFS('Item Log'!C4:C51,A16,'Item Log'!S4:S51,">0") -> 9 | C16: =IFERROR(AVERAGEIFS('Item Log'!S4:S51,'Item Log'!C4:C51,A16,'Item Log'!S4:S51,">0"),"") -> 9 | D16: =IFERROR(percentile.inc(IF('Item Log'!C4:C51=A16,'Item Log'!S4:S51),0.85),"") | E16: =IFERROR(minifs('Item Log'!S4:S51,'Item Log'!C4:C51,A16,'Item Log'!S4:S51,">0"),"") | F16: =IFERROR(maxifs('Item Log'!S4:S51,'Item Log'!C4:C51,A16,'Item Log'!S4:S51,">0"),"")
A17: Tech Debt | B17: =COUNTIFS('Item Log'!C4:C51,A17,'Item Log'!S4:S51,">0") -> 3 | C17: =IFERROR(AVERAGEIFS('Item Log'!S4:S51,'Item Log'!C4:C51,A17,'Item Log'!S4:S51,">0"),"") -> 10 | D17: =IFERROR(percentile.inc(IF('Item Log'!C4:C51=A17,'Item Log'!S4:S51),0.85),"") | E17: =IFERROR(minifs('Item Log'!S4:S51,'Item Log'!C4:C51,A17,'Item Log'!S4:S51,">0"),"") | F17: =IFERROR(maxifs('Item Log'!S4:S51,'Item Log'!C4:C51,A17,'Item Log'!S4:S51,">0"),"")
A18: Spike | B18: =COUNTIFS('Item Log'!C4:C51,A18,'Item Log'!S4:S51,">0") -> 4 | C18: =IFERROR(AVERAGEIFS('Item Log'!S4:S51,'Item Log'!C4:C51,A18,'Item Log'!S4:S51,">0"),"") -> 8 | D18: =IFERROR(percentile.inc(IF('Item Log'!C4:C51=A18,'Item Log'!S4:S51),0.85),"") | E18: =IFERROR(minifs('Item Log'!S4:S51,'Item Log'!C4:C51,A18,'Item Log'!S4:S51,">0"),"") | F18: =IFERROR(maxifs('Item Log'!S4:S51,'Item Log'!C4:C51,A18,'Item Log'!S4:S51,">0"),"")
A21: CYCLE TIME THEO DEV (CONG THUC)
A22: Dev | B22: Count | C22: Avg CT | D22: P85 | E22: Min | F22: Max
A23: Dev_A | B23: =COUNTIFS('Item Log'!D4:D51,A23,'Item Log'!S4:S51,">0") -> 9 | C23: =IFERROR(AVERAGEIFS('Item Log'!S4:S51,'Item Log'!D4:D51,A23,'Item Log'!S4:S51,">0"),"") -> 8 | D23: =IFERROR(percentile.inc(IF('Item Log'!D4:D51=A23,'Item Log'!S4:S51),0.85),"") | E23: =IFERROR(minifs('Item Log'!S4:S51,'Item Log'!D4:D51,A23,'Item Log'!S4:S51,">0"),"") | F23: =IFERROR(maxifs('Item Log'!S4:S51,'Item Log'!D4:D51,A23,'Item Log'!S4:S51,">0"),"")
A24: Dev_B | B24: =COUNTIFS('Item Log'!D4:D51,A24,'Item Log'!S4:S51,">0") -> 16 | C24: =IFERROR(AVERAGEIFS('Item Log'!S4:S51,'Item Log'!D4:D51,A24,'Item Log'!S4:S51,">0"),"") -> 9.625 | D24: =IFERROR(percentile.inc(IF('Item Log'!D4:D51=A24,'Item Log'!S4:S51),0.85),"") | E24: =IFERROR(minifs('Item Log'!S4:S51,'Item Log'!D4:D51,A24,'Item Log'!S4:S51,">0"),"") | F24: =IFERROR(maxifs('Item Log'!S4:S51,'Item Log'!D4:D51,A24,'Item Log'!S4:S51,">0"),"")
A25: Dev_C | B25: =COUNTIFS('Item Log'!D4:D51,A25,'Item Log'!S4:S51,">0") -> 11 | C25: =IFERROR(AVERAGEIFS('Item Log'!S4:S51,'Item Log'!D4:D51,A25,'Item Log'!S4:S51,">0"),"") -> 8.3636364 | D25: =IFERROR(percentile.inc(IF('Item Log'!D4:D51=A25,'Item Log'!S4:S51),0.85),"") | E25: =IFERROR(minifs('Item Log'!S4:S51,'Item Log'!D4:D51,A25,'Item Log'!S4:S51,">0"),"") | F25: =IFERROR(maxifs('Item Log'!S4:S51,'Item Log'!D4:D51,A25,'Item Log'!S4:S51,">0"),"")
A28: PHAN PHOI CT
A29: Range | B29: Count
A30: 1-3d | B30: =COUNTIFS('Item Log'!S4:S51,">="&1,'Item Log'!S4:S51,"<="&3) -> 0
A31: 4-6d | B31: =COUNTIFS('Item Log'!S4:S51,">="&4,'Item Log'!S4:S51,"<="&6) -> 3
A32: 7-9d | B32: =COUNTIFS('Item Log'!S4:S51,">="&7,'Item Log'!S4:S51,"<="&9) -> 26
A33: 10-12d | B33: =COUNTIFS('Item Log'!S4:S51,">="&10,'Item Log'!S4:S51,"<="&12) -> 7
A34: 13d+ | B34: =COUNTIFS('Item Log'!S4:S51,">="&13,'Item Log'!S4:S51,"<="&999) -> 0

Sheet Monte Carlo
A1: MONTE CARLO FORECAST | Cong thuc doc tu Weekly Data
A3: INPUTS (Cong thuc tu dong tu cac sheet khac)
A4: Items con lai | D4: ='Weekly Data'!J14 -> -10 | E4: items
A5: Avg Throughput | D5: =AVERAGE('Weekly Data'!F5:F14) -> 5.7 | E5: items/tuan
A6: Min Throughput | D6: =MIN('Weekly Data'!F5:F14) -> 3 | E6: items/tuan
A7: Max Throughput | D7: =MAX('Weekly Data'!F5:F14) -> 8 | E7: items/tuan
A8: Tuan da qua | D8: =COUNTA('Weekly Data'!A5:A14) -> 10 | E8: tuan
A10: FORECAST (CONG THUC)
A11: Confidence | B11: Tuan Can | C11: Cong Thuc | D11: Giai Thich
A12: 50% (Trung binh) | B12: =IFERROR(ROUND(D4/D5,0),"") -> -2 | C12: Items / Avg TP | E12: Xac suat 50:50
A13: 70% | B13: =IFERROR(ROUND(D4/((D5+D6)/2),0),"") -> -2 | C13: Items / ((Avg+Min)/2) | E13: Kha nang cao
A14: 85% (Cam ket JP) | B14: =IFERROR(ROUND(D4/D6,0),"") -> -3 | C14: Items / Min TP | E14: An toan nhat
A15: 95% | B15: =IFERROR(ROUND(D4/D6*1.2,0),"") -> -4 | C15: Items / Min TP * 1.2 | E15: Buffer 20%
A18: LITTLE'S LAW CHECK (CONG THUC)
A19: WIP Hien Tai | B19: ='Weekly Data'!I14 -> 8 | C19: Tu Weekly Data
A20: Avg Throughput | B20: =D5 -> 5.7 | C20: Tu tren
A21: CT Du Doan (WIP/TP) | B21: =IFERROR(B19/B20,"") -> 1.4035088 | C21: Dinh luat Little
A22: CT Thuc Te (Avg) | B22: =IFERROR(AVERAGEIF('Item Log'!S4:S51,">0"),"") -> 8.8333333 | C22: Tu Item Log
A23: Delta | B23: =IFERROR(B22-B21,"") -> 7.4298246 | C23: Duong=WIP an | Am=flow tot
A24: Status | B24: =IF(ABS(B23)<=1,"On dinh",IF(B23>1,"Co WIP an/bottleneck","Flow tot hon du kien")) -> Co WIP an/bottleneck

Sheet Review Tracker
A1: REVIEW TRACKER | Review Design + Review Code + Review TC | Bottleneck Focus
A2: 3 khau Review la BOTTLENECK lon nhat: Review Design (WIP=2), Review Code (WIP=2), Review TC (WIP=2). Quy tac: REVIEW TRUOC, CODE SAU. Reviewer la nguoi khac (cross-review).
A5: Ma Item | B5: Loai | C5: Implementer | D5: Reviewer | E5: Review Type | F5: Ngay Bat Dau | G5: Ngay Xong | H5: Thoi Gian (ngay) | I5: Status
A6: ITM-003 | B6: Spike | C6: Dev_B | D6: Dev_A | E6: Rev Design | F6: 46120 | G6: 46122 | H6: 2 | I6: Done
A7: ITM-004 | B7: Bug | C7: Dev_B | D7: Dev_A | E7: Rev Design | F7: 46121 | G7: 46122 | H7: 1 | I7: Done
A8: ITM-001 | B8: Bug | C8: Dev_C | D8: Dev_A | E8: Rev Design | F8: 46122 | G8: 46124 | H8: 2 | I8: Done
A9: ITM-002 | B9: Feature | C9: Dev_C | D9: Dev_A | E9: Rev Design | F9: 46123 | G9: 46125 | H9: 2 | I9: Done
A10: ITM-005 | B10: Bug | C10: Dev_B | D10: Dev_A | E10: Rev Design | F10: 46123 | G10: 46124 | H10: 1 | I10: Done
A11: ITM-010 | B11: Feature | C11: Dev_B | D11: Dev_A | E11: Rev Design | F11: 46123 | G11: 46125 | H11: 2 | I11: Done
A12: ITM-003 | B12: Spike | C12: Dev_B | D12: Dev_A | E12: Rev Code | F12: 46124 | G12: 46126 | H12: 2 | I12: Done
A13: ITM-004 | B13: Bug | C13: Dev_B | D13: Dev_A | E13: Rev Code | F13: 46125 | G13: 46126 | H13: 1 | I13: Done
A14: ITM-006 | B14: Feature | C14: Dev_A | D14: Dev_B | E14: Rev Design | F14: 46125 | G14: 46127 | H14: 2 | I14: Done
A15: ITM-007 | B15: Feature | C15: Dev_A | D15: Dev_B | E15: Rev Design | F15: 46125 | G15: 46126 | H15: 1 | I15: Done
A16: ITM-003 | B16: Spike | C16: QA_1 | D16: QA_2 | E16: Rev TC | F16: 46126 | G16: 46128 | H16: 2 | I16: Done
A17: ITM-004 | B17: Bug | C17: QA_2 | D17: QA_1 | E17: Rev TC | F17: 46126 | G17: 46128 | H17: 2 | I17: Done
... A65: ITM-023 | B65: Feature | C65: Dev_A | D65: Dev_B | E65: Rev Code | F65: 46135 | G65: 46137 | H65: 2 | I65: Done
A67: THONG KE REVIEW
A68: Tong Reviews | D68: =COUNTA(A6:A66) -> 60
A69: Avg Review Time | D69: =IFERROR(AVERAGEIF(H6:H66,">0"),0) -> 1.75
A70: Reviews > 2 ngay | D70: =COUNTIF(H6:H66,">2") -> 5
A71: Dang Cho Review | D71: =COUNTIF(I6:I66,"Dang Review") -> 0

Sheet Huong Dan
A1: HUONG DAN SU DUNG — GOOGLE SHEETS COMPATIBLE
A3: QUY TRINH THUC TE
A4: DEV: Detail Design → Review Design → Coding → Review Code → Whitebox (Unit Test)
A5: QA : Test Viewpoint → Test Cases → Review TC → Test Execute (chay song song voi Dev)
A6: FINAL: Acceptance Test (Senior/Leader/PM) → Done
A7: REVIEWER: Nguoi KHAC (review cheo) — Dev_A code thi Dev_B review, QA_1 viet TC thi QA_2 review
A9: Item Log (NGAY)
A10: Nhap NGAY CHINH XAC khi item chuyen sang buoc moi. VD: bat dau Coding → dien ngay vao cot J
A11: Cycle Time, Lead Time, Trang Thai, Phase = TU DONG TINH bang cong thuc
A12: WIP tung buoc = TU DONG DEM bang COUNTIF
A13: Gio Uoc Tinh de bao cao JP. KHONG dung de forecast (dung Throughput thay the)
A15: Daily WIP (NGAY)
... A52: Luu y: Array formula MIN(IF(...)) can Ctrl+Shift+Enter trong GSheets hoac dung MINIFS thay the
